<!-- See LICENSE.md for legal notices. LICENSE.md must be kept together with this file. -->
<mujoco>
    <body name="robot0:palm" pos="1 1.25 0.072" euler="0 -1.5708 0">
        <!--TODO: what the diaginertia should be?-->
        <inertial mass="6.5" pos="0 0 0" ></inertial>
        <geom class="robot0:D_Vizual" pos="0 0 0" name="robot0:V_palm" mesh="robot0:palm" euler="0 0 0"></geom>
        <!--TODO: what the childclass refer to? and I am not sure the pos and euler.......-->
        <body childclass="robot0:asset_class" name="robot0:fp1" pos="0 0.051 -0.015" euler="0 0 0">
            <!-- <inertial pos="0.001 -0.002 0.29" quat="0.982 -0.016 0 -0.188" mass="0.08"></inertial> -->
            <!-- <inertial mass="0.08"></inertial> -->
            <joint name="robot0:fpj1" type="hinge" pos="0 0 0" axis="1 0 0" range="-0.785398 0.785398" damping="0.00" armature="0.005" user="1123"></joint>
            <geom class="robot0:D_Vizual" pos="0 0 0" name="robot0:V_fp1" mesh="robot0:proximal" euler="0 0 0"></geom>
            <site name="robot0:fps1" pos="0 0 0"></site>
            <body name="robot0:fd1" pos="0 0 -0.07">
                <!-- <inertial pos="0.003 0 0.016" quat="0.504 0.496 0.495 0.504" mass="0.07"></inertial> -->
                <joint name="robot0:fdj1" type="hinge" pos="0 0 0" axis="-1 0 0" range="0 1.5708" damping="0.0" armature="0.005" user="1123"></joint>
                <geom class="robot0:D_Vizual" name="robot0:V_fd1" mesh="robot0:distal"></geom>
                <site name="robot0:fds1" pos="0 0 0"></site>
            </body>
        </body>
        <body childclass="robot0:asset_class" name="robot0:fp2" pos="0 -0.051 -0.015" euler="0 0 3.1416">
            <!-- <inertial pos="0.001 -0.002 0.29" quat="0.982 -0.016 0 -0.188" mass="0.08"></inertial> -->
            <joint name="robot0:fpj2" type="hinge" pos="0 0 0" axis="1 0 0" range="-0.785398 0.785398" damping="0.0" armature="0.005" user="1123"></joint>
            <geom class="robot0:D_Vizual" pos="0 0 0" name="robot0:V_fp2" mesh="robot0:proximal" euler="0 0 0"></geom>
            <site name="robot0:fps2" pos="0 0 0"></site>
            <body name="robot0:fd2" pos="0 0 -0.07">
                <!-- <inertial pos="0.003 0 0.016" quat="0.504 0.496 0.495 0.504" mass="0.07"></inertial> -->
                <joint name="robot0:fdj2" type="hinge" pos="0 0 0" axis="-1 0 0" range="0 1.5708" damping="0.0" armature="0.005" user="1123"></joint>
                <geom class="robot0:D_Vizual" name="robot0:V_fd2" mesh="robot0:distal"></geom>
                <site name="robot0:fds2" pos="0 0 0"></site>
            </body>
        </body>
    </body>
</mujoco>
