<mujoco model="swimmer">
  <compiler angle="degree" coordinate="local" inertiafromgeom="true"/>
  <option collision="predefined" density="4000" integrator="RK4" timestep="0.01" viscosity="0.1"/>
  <default>
    <geom conaffinity="1" condim="1" contype="1" material="geom" rgba="0.8 0.6 .4 1"/>
    <joint armature='0.1'  />
  </default>
  <asset>
    <texture builtin="gradient" height="100" rgb1="1 1 1" rgb2="0 0 0" type="skybox" width="100"/>
    <texture builtin="flat" height="1278" mark="cross" markrgb="1 1 1" name="texgeom" random="0.01" rgb1="0.8 0.6 0.4" rgb2="0.8 0.6 0.4" type="cube" width="127"/>
    <texture builtin="checker" height="100" name="texplane" rgb1="0 0 0" rgb2="0.8 0.8 0.8" type="2d" width="100"/>
    <material name="MatPlane" reflectance="0.5" shininess="1" specular="1" texrepeat="30 30" texture="texplane"/>
    <material name="geom" texture="texgeom" texuniform="true"/>
  </asset>
  <worldbody>
    <light cutoff="100" diffuse="1 1 1" dir="-0 0 -1.3" directional="true" exponent="1" pos="0 0 1.3" specular=".1 .1 .1"/>
    <geom conaffinity="1" condim="3" material="MatPlane" name="floor" pos="0 0 -0.1" rgba="0.8 0.9 0.8 1" size="40 40 0.1" type="plane"/>
    <!--  ================= SWIMMER ================= /-->
    <body name="torso" pos="10 0 0">
      <geom density="1000" fromto="1.5 0 0 0.5 0 0" size="0.1" type="capsule"/>
      <joint axis="1 0 0" name="slider1" pos="0 0 0" type="slide"/>
      <joint axis="0 1 0" name="slider2" pos="0 0 0" type="slide"/>
      <joint axis="0 0 1" name="rot" pos="0 0 0" type="hinge"/>
      <body name="2" pos="0.5 0 0">
        <geom density="1000" fromto="0 0 0 -1 0 0" size="0.1" type="capsule"/>
        <joint axis="0 0 1" limited="true" name="rot2" pos="0 0 0" range="-100 100" type="hinge"/>
        <body name="3" pos="-1 0 0">
          <geom density="1000" fromto="0 0 0 -1 0 0" size="0.1" type="capsule"/>
          <joint axis="0 0 1" limited="true" name="rot3" pos="0 0 0" range="-100 100" type="hinge"/>
          <body name="4" pos="-1 0 0">
            <geom density="1000" fromto="0 0 0 -1 0 0" size="0.1" type="capsule"/>
            <joint axis="0 0 1" limited="true" name="rot4" pos="0 0 0" range="-100 100" type="hinge"/>
            <body name="5" pos="-1 0 0">
              <geom density="1000" fromto="0 0 0 -1 0 0" size="0.1" type="capsule"/>
              <joint axis="0 0 1" limited="true" name="rot5" pos="0 0 0" range="-100 100" type="hinge"/>       
              <body name="6" pos="-1 0 0">
                <geom density="1000" fromto="0 0 0 -1 0 0" size="0.1" type="capsule"/>
                <joint axis="0 0 1" limited="true" name="rot6" pos="0 0 0" range="-100 100" type="hinge"/>
                <body name="7" pos="-1 0 0">
                  <geom density="1000" fromto="0 0 0 -1 0 0" size="0.1" type="capsule"/>
                  <joint axis="0 0 1" limited="true" name="rot7" pos="0 0 0" range="-100 100" type="hinge"/>
                  <body name="8" pos="-1 0 0">
                    <geom density="1000" fromto="0 0 0 -1 0 0" size="0.1" type="capsule"/>
                    <joint axis="0 0 1" limited="true" name="rot8" pos="0 0 0" range="-100 100" type="hinge"/>
                    <body name="9" pos="-1 0 0">
                      <geom density="1000" fromto="0 0 0 -1 0 0" size="0.1" type="capsule"/>
                      <joint axis="0 0 1" limited="true" name="rot9" pos="0 0 0" range="-100 100" type="hinge"/>
                      <body name="10" pos="-1 0 0">
                        <geom density="1000" fromto="0 0 0 -1 0 0" size="0.1" type="capsule"/>
                        <joint axis="0 0 1" limited="true" name="rot10" pos="0 0 0" range="-100 100" type="hinge"/>
                        <body name="11" pos="-1 0 0">
                          <geom density="1000" fromto="0 0 0 -1 0 0" size="0.1" type="capsule"/>
                          <joint axis="0 0 1" limited="true" name="rot11" pos="0 0 0" range="-100 100" type="hinge"/>
                          <body name="12" pos="-1 0 0">
                            <geom density="1000" fromto="0 0 0 -1 0 0" size="0.1" type="capsule"/>
                            <joint axis="0 0 1" limited="true" name="rot12" pos="0 0 0" range="-100 100" type="hinge"/>
                            <body name="13" pos="-1 0 0">
                              <geom density="1000" fromto="0 0 0 -1 0 0" size="0.1" type="capsule"/>
                              <joint axis="0 0 1" limited="true" name="rot13" pos="0 0 0" range="-100 100" type="hinge"/>
                              <body name="14" pos="-1 0 0">
                                <geom density="1000" fromto="0 0 0 -1 0 0" size="0.1" type="capsule"/>
                                <joint axis="0 0 1" limited="true" name="rot14" pos="0 0 0" range="-100 100" type="hinge"/>
                                <body name="15" pos="-1 0 0">
                                  <geom density="1000" fromto="0 0 0 -1 0 0" size="0.1" type="capsule"/>
                                  <joint axis="0 0 1" limited="true" name="rot15" pos="0 0 0" range="-100 100" type="hinge"/>
                                  <body name="16" pos="-1 0 0">
                                    <geom density="1000" fromto="0 0 0 -1 0 0" size="0.1" type="capsule"/>
                                    <joint axis="0 0 1" limited="true" name="rot16" pos="0 0 0" range="-100 100" type="hinge"/>
                                    <body name="17" pos="-1 0 0">
                                      <geom density="1000" fromto="0 0 0 -1 0 0" size="0.1" type="capsule"/>
                                      <joint axis="0 0 1" limited="true" name="rot17" pos="0 0 0" range="-100 100" type="hinge"/>
                                      <body name="18" pos="-1 0 0">
                                        <geom density="1000" fromto="0 0 0 -1 0 0" size="0.1" type="capsule"/>
                                        <joint axis="0 0 1" limited="true" name="rot18" pos="0 0 0" range="-100 100" type="hinge"/>
                                        <body name="19" pos="-1 0 0">
                                          <geom density="1000" fromto="0 0 0 -1 0 0" size="0.1" type="capsule"/>
                                          <joint axis="0 0 1" limited="true" name="rot19" pos="0 0 0" range="-100 100" type="hinge"/>
                                          <body name="20" pos="-1 0 0">
                                            <geom density="1000" fromto="0 0 0 -1 0 0" size="0.1" type="capsule"/>
                                            <joint axis="0 0 1" limited="true" name="rot20" pos="0 0 0" range="-100 100" type="hinge"/>         
                                          </body>         
                                        </body>      
                                      </body>        
                                    </body>        
                                  </body>       
                                </body>        
                              </body>         
                            </body>         
                          </body>         
                        </body>         
                      </body>          
                    </body>          
                  </body>          
                </body>        
              </body>              
            </body>              
          </body>          
        </body>
      </body>
    </body>
  </worldbody>
  <actuator>
    <motor ctrllimited="true" ctrlrange="-1 1" gear="150.0" joint="rot"/>
    <motor ctrllimited="true" ctrlrange="-1 1" gear="150.0" joint="rot2"/>
    <motor ctrllimited="true" ctrlrange="-1 1" gear="150.0" joint="rot3"/>
    <motor ctrllimited="true" ctrlrange="-1 1" gear="150.0" joint="rot4"/>
    <motor ctrllimited="true" ctrlrange="-1 1" gear="150.0" joint="rot5"/>
    <motor ctrllimited="true" ctrlrange="-1 1" gear="150.0" joint="rot6"/>
    <motor ctrllimited="true" ctrlrange="-1 1" gear="150.0" joint="rot7"/>
    <motor ctrllimited="true" ctrlrange="-1 1" gear="150.0" joint="rot8"/>
    <motor ctrllimited="true" ctrlrange="-1 1" gear="150.0" joint="rot9"/>
    <motor ctrllimited="true" ctrlrange="-1 1" gear="150.0" joint="rot10"/>
    <motor ctrllimited="true" ctrlrange="-1 1" gear="150.0" joint="rot11"/>
    <motor ctrllimited="true" ctrlrange="-1 1" gear="150.0" joint="rot12"/>
    <motor ctrllimited="true" ctrlrange="-1 1" gear="150.0" joint="rot13"/>
    <motor ctrllimited="true" ctrlrange="-1 1" gear="150.0" joint="rot14"/>
    <motor ctrllimited="true" ctrlrange="-1 1" gear="150.0" joint="rot15"/>
    <motor ctrllimited="true" ctrlrange="-1 1" gear="150.0" joint="rot16"/>
    <motor ctrllimited="true" ctrlrange="-1 1" gear="150.0" joint="rot17"/>
    <motor ctrllimited="true" ctrlrange="-1 1" gear="150.0" joint="rot18"/>
    <motor ctrllimited="true" ctrlrange="-1 1" gear="150.0" joint="rot19"/>
    <motor ctrllimited="true" ctrlrange="-1 1" gear="150.0" joint="rot20"/>
  </actuator>
</mujoco>
